<?xml version="1.0" ?>
<!-- =================================================================================== -->
<!-- |    This document was autogenerated by xacro from /home/rdtintern/catkin_ws/src/cyton_gamma_300_description/cyton_gamma_300.urdf.xacro | -->
<!-- |    EDITING THIS FILE BY HAND IS NOT RECOMMENDED                                 | -->
<!-- =================================================================================== -->
<robot name="cyton_gamma_300" xmlns:xacro="http://www.ros.org/wiki/xacro">
  <!-- Initial footprint motor used here -->
  <link name="base_footprint">
    <visual>
      <origin rpy="0 0 0" xyz="0 0 0"/>
      <geometry>
        <sphere radius="0.001"/>
      </geometry>
      <material name="white">
        <color rgba="1 1 1 1"/>
      </material>
    </visual>
  </link>
  <joint name="base_joint" type="fixed">
    <parent link="base_footprint"/>
    <child link="base_link"/>
    <origin rpy="0 0 0" xyz="0.0 0.0 0.0"/>
  </joint>
  <!-- Base of robot here -->
  <link name="base_link">
    <visual>
      <origin rpy="0 0 0" xyz="0 0 0"/>
      <geometry>
        <mesh filename="package://cyton_gamma_300_description/meshes/gamma_base.dae"/>
      </geometry>
    </visual>
    <collision>
      <origin xyz="0 0.0115 0.047"/>
      <geometry>
        <box size="0.154 0.177 0.094"/>
      </geometry>
    </collision>
  </link>
  <!-- First motor located here -->
  <joint name="shoulder_roll_joint" type="revolute">
    <parent link="base_link"/>
    <child link="shoulder_roll"/>
    <origin rpy="0 0 1.2" xyz="0 0 0.05315"/>
    <limit effort="100.0" lower="-2.618" upper="2.618" velocity="1.0"/>
    <axis xyz="0 0 1"/>
  </joint>
  <link name="shoulder_roll">
    <visual>
      <origin rpy="1.5708 0 3.14159" xyz="0 0 0"/>
      <geometry>
        <mesh filename="package://cyton_gamma_300_description/meshes/Shoulder_Roll.dae"/>
      </geometry>
    </visual>
    <collision>
      <origin xyz="0.0 0.069 0.0587"/>
      <geometry>
        <box size="0.09829 0.18143 0.08392"/>
      </geometry>
    </collision>
  </link>
  <!-- Second motor located here -->
  <joint name="shoulder_pitch_joint" type="revolute">
    <parent link="shoulder_roll"/>
    <child link="shoulder_pitch"/>
    <origin rpy="1.2 0 0" xyz="0 0 0.063"/>
    <limit effort="100.0" lower="-1.8326" upper="1.8326" velocity="1.0"/>
    <axis xyz="1 0 0"/>
  </joint>
  <link name="shoulder_pitch">
    <visual>
      <origin rpy="0 1.5708 0" xyz="0.028 0 0"/>
      <geometry>
        <mesh filename="package://cyton_gamma_300_description/meshes/Shoulder_Pitch.dae"/>
      </geometry>
    </visual>
    <collision>
      <origin xyz="-0.001 0.064 0.1745"/>
      <geometry>
        <box size="0.0709 0.19363 0.083"/>
      </geometry>
    </collision>
  </link>
  <!-- Third motor located here -->
  <joint name="elbow_roll_joint" type="revolute">
    <parent link="shoulder_pitch"/>
    <child link="elbow_roll"/>
    <origin rpy="0 0 1.2" xyz="0 0 0.089"/>
    <limit effort="100.0" lower="-1.8326" upper="1.8326" velocity="1.0"/>
    <axis xyz="0 0 1"/>
  </joint>
  <link name="elbow_roll">
    <visual>
      <origin rpy="0 0 3.92699" xyz="0 0 0"/>
      <geometry>
        <mesh filename="package://cyton_gamma_300_description/meshes/Elbow_Roll.dae"/>
      </geometry>
    </visual>
    <collision>
      <origin xyz="-0.0225 0.039 0.3068"/>
      <geometry>
        <box size="0.0717 0.1846 0.0756"/>
      </geometry>
    </collision>
  </link>
  <!-- Fourth motor located here -->
  <joint name="elbow_pitch_joint" type="revolute">
    <parent link="elbow_roll"/>
    <child link="elbow_pitch"/>
    <origin rpy="1.2 0 0" xyz="0 0 0.052"/>
    <limit effort="100.0" lower="-1.8326" upper="1.8326" velocity="1.0"/>
    <axis xyz="1 0 0"/>
  </joint>
  <link name="elbow_pitch">
    <visual>
      <!-- Not sure if this is the correct orientation. -->
      <origin rpy="1.5708 0 1.5708" xyz="0.027 0 0"/>
      <geometry>
        <mesh filename="package://cyton_gamma_300_description/meshes/Elbow_Pitch.dae"/>
      </geometry>
    </visual>
    <collision>
      <origin xyz="0.0346 0.0461 0.4228"/>
      <geometry>
        <box size="0.0549 0.1557 0.076"/>
      </geometry>
    </collision>
  </link>
  <!-- Fifth motor located here -->
  <joint name="elbow_yaw_joint" type="revolute">
    <parent link="elbow_pitch"/>
    <child link="elbow_yaw"/>
    <origin rpy="0 -1.2 0" xyz="0 0 0.072"/>
    <limit effort="100.0" lower="-1.8326" upper="1.8326" velocity="1.0"/>
    <axis xyz="0 -1 0"/>
  </joint>
  <link name="elbow_yaw">
    <visual>
      <origin rpy="1.5708 0 0" xyz="0 0 0"/>
      <geometry>
        <mesh filename="package://cyton_gamma_300_description/meshes/Elbow_Yaw.dae"/>
      </geometry>
    </visual>
    <collision>
      <origin xyz="0.0172 0.0209 0.516"/>
      <geometry>
        <box size="0.0535 0.1160 0.0402"/>
      </geometry>
    </collision>
  </link>
  <!-- Sixth motor located here -->
  <joint name="wrist_pitch_joint" type="revolute">
    <parent link="elbow_yaw"/>
    <child link="wrist_pitch"/>
    <origin rpy="1.2 0 0" xyz="0 0 0.0718"/>
    <limit effort="100.0" lower="-1.8326" upper="1.8326" velocity="1.0"/>
    <axis xyz="1 0 0"/>
  </joint>
  <link name="wrist_pitch">
    <visual>
      <origin rpy="1.5708 0 1.5708" xyz="0.027 0 0"/>
      <geometry>
        <mesh filename="package://cyton_gamma_300_description/meshes/Wrist_Pitch.dae"/>
      </geometry>
    </visual>
    <collision>
      <origin xyz="0.0257 0.0118 0.5617"/>
      <geometry>
        <box size="0.026 0.0435 0.05185"/>
      </geometry>
    </collision>
  </link>
  <!-- Seventh motor located here -->
  <joint name="wrist_roll_joint" type="revolute">
    <parent link="wrist_pitch"/>
    <child link="wrist_roll"/>
    <origin rpy="0 0 1.2" xyz="0 0 0.051425"/>
    <limit effort="100.0" lower="-2.61799" upper="2.61799" velocity="1.0"/>
    <axis xyz="0 0 1"/>
  </joint>
  <link name="wrist_roll">
    <visual>
      <origin rpy="0 3.14159 1.5708" xyz="0 0 0"/>
      <geometry>
        <mesh filename="package://cyton_gamma_300_description/meshes/Wrist_Roll.dae"/>
      </geometry>
    </visual>
    <collision>
      <origin xyz="-0.0063 -0.0014 0.6102"/>
      <geometry>
        <box size="0.0518 0.0723 0.1004"/>
      </geometry>
    </collision>
  </link>
  <!-- Eigth motor located here -->
  <joint name="gripper_joint" type="prismatic">
    <parent link="wrist_roll"/>
    <child link="gripper_finger1"/>
    <origin rpy="0 0 0" xyz="-0.01331 0.00485 0.077225"/>
    <limit effort="100.0" lower="-0.5" upper="1.9" velocity="1.0"/>
    <axis xyz="1 0 0"/>
  </joint>
  <link name="gripper_finger1">
    <visual>
      <origin rpy="0 0 0" xyz="0 0 0"/>
      <geometry>
        <mesh filename="package://cyton_gamma_300_description/meshes/Gripper_Finger1.dae"/>
      </geometry>
    </visual>
    <collision>
      <origin xyz="-0.0167 0.0172 0.7254"/>
      <geometry>
        <box size="0.015 0.0229 0.0475"/>
      </geometry>
    </collision>
  </link>
  <!-- Eighth motor located here -->
  <joint name="gripper_joint2" type="prismatic">
    <parent link="wrist_roll"/>
    <child link="gripper_finger2"/>
    <origin rpy="0 0 0" xyz="0.0098 0.00485 0.077225"/>
    <limit effort="100.0" lower="-0.008" upper="0.008" velocity="1.0"/>
    <mimic joint="gripper_joint" multiplier="-1"/>
    <axis xyz="1 0 0"/>
  </joint>
  <link name="gripper_finger2">
    <visual>
      <origin rpy="0 0 0" xyz="0 0 0"/>
      <geometry>
        <mesh filename="package://cyton_gamma_300_description/meshes/Gripper_Finger2.dae"/>
      </geometry>
    </visual>
    <collision>
      <origin xyz="0.0132 0.0172 0.7254"/>
      <geometry>
        <box size="0.015 0.0229 0.0475"/>
      </geometry>
    </collision>
  </link>
  <!-- virtual end-effector -->
  <joint name="virtual_endeffector_joint" type="fixed">
    <parent link="wrist_roll"/>
    <child link="virtual_endeffector"/>
    <origin rpy="0 0 0" xyz="-0.002316 0.0079 0.079425"/>
  </joint>
  <link name="virtual_endeffector">
    <visual>
      <origin rpy="0 0 0" xyz="0 0 0"/>
      <geometry>
        <sphere radius="0.002"/>
      </geometry>
      <material name="grey">
        <color rgba="0.7 0.7 0.7 0.8"/>
      </material>
    </visual>
  </link>
</robot>
